x = 10
try:
  print("print statement inside try block")
  print(x)
except:
  print("an exception occurred")