try:
  print("print statement inside try block")
  raise Exception("Exception")
except:
  print("an exception occurred")